Workbook

Sheet Content Inventory
A1: Day | B1: Module # | C1: Session or Module Name | D1: Estimated Minutes | E1: Content Type | F1: Artifact Type 1 | G1: Artifact Type 2 | H1: Artifact Type 3 | I1: Learner Outcome in Plain Language | J1: Decisions the Learner Must Make | K1: Systems or Tools Touched | L1: Notes | M1: Status
A2: 3 | B2: D3.01 | C2: Welcome & Billing Overview | D2: 15 | E2: ILT | F2: Facilitator Guide | G2: Slide Deck | I2: I understand what Conservice does, what the billing role expects of me, how I'm supposed to behave during training, and how to ask good questions when I'm stuck. | J2: Which of the BOB tenets will be hardest for me to live out and why? When do I try to solve a problem on my own versus asking for help? What does 'owning the experience' look like for me personally? | K2: Zoom | M2: Built
A3: 3 | B3: D3.02 | C3: The Big Picture: 6-Step Billing Lifecycle | D3: 90 | E3: ILT | F3: Facilitator Guide | G3: Slide Deck | I3: I understand the 6-step billing lifecycle, how my daily work connects to client outcomes, what my performance will be measured by, and why every step depends on the one before it. | J3: Which BOB tenet will stretch me most and why? Who ultimately pays for our services — the resident or the property manager? Why is chat responsiveness tied to client outcomes, not just professionalism? What is missing from this question before I ask it? Which of the five core skills am I strongest in, and which do I need to work on? | K3: Zoom, HRX | M3: Built
A4: 3 | B4: D3.03 | C4: Tool Navigation | D4: 45 | E4: Blended | F4: Facilitator Guide | G4: eLearning Module | H4: Knowledge Base Article | I4: I know where each system lives in the billing workflow, how to open and navigate a task in Skywalker, how to pull up a bill in Foxit, and where provider data gets entered in Fusion — so I don't get lost on my first real task. | J4: Which system do I open first for this task? Am I in the right tab in Skywalker before I start entering data? Does this bill in Foxit match the account and cycle I'm working on? Is there a CSR Alert I need to read before I can move forward? | K4: Skywalker, Foxit, Fusion 2.0, Email/Inbox, Knowledge Base | M4: Built
A5: 3 | B5: D3.04 | C5: Inbox & Macro Setup | D5: 30 | E5: ILT | F5: Job Aid | G5: Facilitator Guide | I5: ⚠️ DRAFT — I can configure my Outlook/Gmail inbox with the folders, filters, and macros I'll use every day so my email doesn't become a bottleneck. | J5: ⚠️ DRAFT — Which emails get filtered automatically vs. need my attention? Which macros do I set up first? | K5: Email/Inbox, Outlook or Gmail | L5: Setup task — pair with IT/onboarding checklist | M5: Draft
A6: 3 | B6: D3.05 | C6: Intro to Provider Bills: Reading Key Bill Elements | D6: 40 | E6: ILT | F6: Facilitator Guide | G6: Slide Deck | H6: Sample Bills | I6: ⚠️ DRAFT — I can identify the key elements on a provider bill (account number, service period, charges, usage) and know which fields matter for prep work. | J6: ⚠️ DRAFT — Is this the right bill for the right cycle? Which charges are billable to residents vs. property? | K6: Foxit, Provider portals | L6: Pair with sample bills from real providers | M6: Draft
A7: 3 | B7: D3.06 | C7: Distinguishing Similar-Looking Values on a Bill | D7: 30 | E7: ILT | F7: Activity | G7: Sample Bills | I7: ⚠️ DRAFT — I can tell the difference between values that look similar on a provider bill (current charges vs. previous balance, total due vs. amount billed) so I enter the right number. | J7: ⚠️ DRAFT — Which value am I supposed to enter into Fusion? Does the number on the bill match what I'm about to type? | K7: Foxit, Fusion 2.0 | L7: High-repetition activity recommended | M7: Draft
A8: 3 | B8: D3.07 | C8: Prep — Fusion 2.0 & Spreadsheet Simulations | D8: 60 | E8: Simulation | F8: Facilitator Guide | G8: Job Aid | I8: ⚠️ DRAFT — I can complete a prep task in Fusion 2.0 and on a holding spreadsheet, knowing when to use which and how the two connect. | J8: ⚠️ DRAFT — Fusion or spreadsheet for this prop? Did I check the Fusion notes before entering data? | K8: Fusion 2.0, Spreadsheets, YODA | M8: Draft
A9: 3 | B9: D3.08 | C9: Data Entry Accuracy: Common Failure Points & QC Habits | D9: 30 | E9: ILT | F9: Job Aid | G9: Facilitator Guide | I9: ⚠️ DRAFT — I know the top sources of data entry errors in Fusion 2.0 and the habits that catch them before they leave my desk. | J9: ⚠️ DRAFT — Did I double-check this entry? What's my self-QC habit for each field? | K9: Fusion 2.0 | L9: Ties to AQC 80% target | M9: Draft
A10: 3 | B10: D3.09 | C10: NB / NUFB / State Regulations | D10: 15 | E10: ILT | F10: Facilitator Guide | G10: Reference Doc | I10: ⚠️ DRAFT — I know what NB and NUFB mean and where state regulations affect what we can and can't bill. | J10: ⚠️ DRAFT — Is this property in a regulated state? Does this charge comply? | K10: Knowledge Base, YODA | L10: Awareness-level only on Day 3 | M10: Draft
A11: 3 | B11: D3.10 | C11: Client Communication — Introduction to Professional Email & Why It Matters | D11: 30 | E11: ILT | F11: Facilitator Guide | G11: Slide Deck | H11: Mock Email Template | I11: ⚠️ DRAFT — I understand why client communication matters at Conservice, the elements of a professional email, and when to ask for help instead of guessing. | J11: ⚠️ DRAFT — Is this email professional enough to send? Do I need to loop in my lead? | K11: Email, Knowledge Base | L11: Foundation for Day 4+ mock email practice | M11: Draft
A12: 3 | B12: D3.11 | C12: EOD 3 Review | D12: 15 | E12: ILT | F12: Facilitator Guide | I12: ⚠️ DRAFT — I can name the 6 lifecycle steps, the 6 core systems, and the BOB tenets without prompting. | J12: ⚠️ DRAFT — What did I learn today that I need to revisit tonight? | K12: Zoom | L12: Daily close-out | M12: Draft
A13: 4 | B13: D4.01 | C13: Day 4 Morning Review | D13: 15 | E13: ILT | F13: Facilitator Guide | I13: ⚠️ DRAFT — I can recall the key Day 3 concepts and ask questions on anything that didn't stick. | J13: ⚠️ DRAFT — What from yesterday do I need clarification on? | K13: Zoom | L13: Daily warm-up | M13: Draft
A14: 4 | B14: D4.02 | C14: Intro to Skywalker | D14: 45 | E14: ILT | F14: Facilitator Guide | G14: Slide Deck | H14: Job Aid | I14: ⚠️ DRAFT — I can log into Skywalker, navigate the main views, and understand how it differs from YODA. | J14: ⚠️ DRAFT — Skywalker or YODA for this task? | K14: Skywalker | M14: Draft
A15: 4 | B15: D4.03 | C15: Bill Methods & Bill Setup — High-Level Introduction | D15: 45 | E15: ILT | F15: Facilitator Guide | G15: Slide Deck | I15: ⚠️ DRAFT — I understand the major bill methods at a high level and know where bill setup lives in the system. | J15: ⚠️ DRAFT — Which method applies to this property? | K15: YODA, Skywalker | L15: Depth comes Day 6-7 | M15: Draft
A16: 4 | B16: D4.04 | C16: Regulations | D16: 20 | E16: ILT | F16: Facilitator Guide | G16: Reference Doc | I16: ⚠️ DRAFT — I know the categories of state regulations that affect billing and where to look them up. | J16: ⚠️ DRAFT — Is this state regulated? Where do I check? | K16: Knowledge Base | M16: Draft
A17: 4 | B17: D4.05 | C17: Bill Dates Tab (2 Part) | D17: 60 | E17: ILT | F17: Facilitator Guide | G17: Slide Deck | H17: Dev YODA Practice | I17: I can correctly set bill dates in YODA — rent dates, Conservice utility dates, post month, and total date range — and I know when to flag a date that doesn't look right. | J17: Does the post month match the cycle? Are rent and Conservice dates aligned? Do I need to escalate this date setup? | K17: YODA, Dev YODA | L17: Krista pending on Dev YODA property access | M17: Built
A18: 4 | B18: D4.06 | C18: Future Cycle Calculator (FCC) | D18: 30 | E18: ILT | F18: Facilitator Guide | G18: Job Aid | I18: ⚠️ DRAFT — I know what FCC is, what it does, and that I'll learn the mechanics in Day 8 Exceptions. | J18: ⚠️ DRAFT — Awareness only — when would I use FCC? | K18: YODA | L18: Mechanics deferred to Day 8 | M18: Draft
A19: 4 | B19: D4.07 | C19: MIMO: What It Is and Where It Falls in the Workflow | D19: 30 | E19: ILT | F19: Facilitator Guide | G19: Slide Deck | I19: ⚠️ DRAFT — I understand what MIMO (Move-In/Move-Out) is and where it fits in the billing workflow. | J19: ⚠️ DRAFT — Is this a MIMO scenario? What does the cycle look like? | K19: YODA, Skywalker | L19: Deeper dive Day 5/7 | M19: Draft
A20: 4 | B20: D4.08 | C20: Scenario — Troubleshoot a Bill Dates Task | D20: 30 | E20: Scenario | F20: Facilitator Guide | G20: Scenario Card | I20: ⚠️ DRAFT — I can work through a bill dates scenario and identify what's wrong before fixing it. | J20: ⚠️ DRAFT — What's wrong here? What's my next move? | K20: YODA, Skywalker | M20: Draft
A21: 4 | B21: D4.09 | C21: Simulation — SW Bill Dates Task Error / Manual Bill Dates Exception | D21: 45 | E21: Simulation | F21: Facilitator Guide | G21: Job Aid | I21: ⚠️ DRAFT — I can resolve a Skywalker bill dates task error and a manual bill dates exception in YODA. | J21: ⚠️ DRAFT — What's the exception telling me? What's the fix? | K21: Skywalker, YODA | M21: Draft
A22: 4 | B22: D4.10 | C22: Client Communication — Grading Rubric, BOB Tenets, Mock Emails | D22: 30 | E22: Activity | F22: Facilitator Guide | G22: Rubric | H22: Mock Email Set | I22: ⚠️ DRAFT — I can write a professional client email and self-assess it against the grading rubric tied to BOB tenets. | J22: ⚠️ DRAFT — Does my email meet the rubric? Which tenet does it reflect? | K22: Email | L22: Rubric introduced here, used Day 5-10 | M22: Draft
A23: 4 | B23: D4.11 | C23: EOD 4 Review | D23: 15 | E23: ILT | F23: Facilitator Guide | I23: ⚠️ DRAFT — I can summarize bill dates, FCC awareness, and Skywalker basics from today. | J23: ⚠️ DRAFT — What do I revisit tonight? | K23: Zoom | L23: 1.5 practice / 1 hr admin time in afternoon | M23: Draft
A24: 5 | B24: D5.01 | C24: Day 5 Morning Review | D24: 15 | E24: ILT | F24: Facilitator Guide | I24: ⚠️ DRAFT — I can recall Day 4 concepts and ask follow-up questions. | J24: ⚠️ DRAFT — What needs clarification? | K24: Zoom | M24: Draft
A25: 5 | B25: D5.02 | C25: Billing Process Overview | D25: 45 | E25: ILT | F25: Facilitator Guide | G25: Slide Deck | I25: ⚠️ DRAFT — I can walk through the end-to-end billing process and place each Day 5 topic within it. | J25: ⚠️ DRAFT — Where in the process am I right now? | K25: YODA, Skywalker | L25: Anchors UA and Stats discussions | M25: Draft
A26: 5 | B26: D5.03 | C26: MIMO & Stats Tabs — Introduction | D26: 45 | E26: ILT | F26: Facilitator Guide | G26: Job Aid | I26: ⚠️ DRAFT — I can navigate the MIMO and Stats tabs in YODA and explain what each one drives. | J26: ⚠️ DRAFT — Are the stats correct? Did MIMO process cleanly? | K26: YODA | M26: Draft
A27: 5 | B27: D5.04 | C27: Utility Amounts Tab | D27: 60 | E27: ILT | F27: Facilitator Guide | G27: Job Aid | H27: Simulation | I27: ⚠️ DRAFT — I can verify and enter admin/flat amounts, RUBS provider amounts, and check frequency in the UA tab. | J27: ⚠️ DRAFT — Does this UA entry match the bill? Is the frequency right? | K27: YODA, Fusion 2.0 | M27: Draft
A28: 5 | B28: D5.05 | C28: Inputting Provider Amounts | D28: 45 | E28: Simulation | F28: Facilitator Guide | G28: Job Aid | I28: ⚠️ DRAFT — I can input provider amounts from a bill into UA correctly the first time. | J28: ⚠️ DRAFT — Right amount? Right line? Right frequency? | K28: YODA, Fusion 2.0, Foxit | M28: Draft
A29: 5 | B29: D5.06 | C29: Comparing UA Admin Amounts to Bill Setup / Fee Screen | D29: 30 | E29: ILT | F29: Facilitator Guide | G29: Job Aid | I29: ⚠️ DRAFT — I can compare UA admin amounts to Bill Setup and the Fee Screen and spot mismatches. | J29: ⚠️ DRAFT — Do these three agree? If not, which is right? | K29: YODA | M29: Draft
A30: 5 | B30: D5.07 | C30: What Good Documentation Looks Like | D30: 20 | E30: ILT | F30: Facilitator Guide | G30: Example Notes | I30: ⚠️ DRAFT — I know what a good Fusion/YODA note looks like, why it matters downstream, and the standards I'm expected to meet. | J30: ⚠️ DRAFT — Will the next person reading this note know what I did and why? | K30: YODA, Fusion 2.0 | L30: Sets foundation for exception notes Day 8 | M30: Draft
A31: 5 | B31: D5.08 | C31: Scenario — Base Fee / Service Fee Change or Unusual Cycle Length | D31: 30 | E31: Scenario | F31: Facilitator Guide | G31: Scenario Card | I31: ⚠️ DRAFT — I can work through a scenario involving a fee change or odd cycle and identify what to flag. | J31: ⚠️ DRAFT — What changed? Why? Who needs to know? | K31: YODA, Skywalker | M31: Draft
A32: 5 | B32: D5.09 | C32: Simulation — SW UA Task Error / Manual UA Exception | D32: 45 | E32: Simulation | F32: Facilitator Guide | G32: Job Aid | I32: ⚠️ DRAFT — I can resolve a Skywalker UA task and a manual UA exception in YODA. | J32: ⚠️ DRAFT — What does the exception say? What's the fix? | K32: Skywalker, YODA | M32: Draft
A33: 5 | B33: D5.10 | C33: Client Communication — Mock Emails, BOB Tenets | D33: 30 | E33: Activity | F33: Facilitator Guide | G33: Rubric | H33: Mock Email Set | I33: ⚠️ DRAFT — I can write a Day 5-level client email and self-grade against the rubric. | J33: ⚠️ DRAFT — Does this email pass the rubric? | K33: Email | M33: Draft
A34: 5 | B34: D5.11 | C34: EOD 5 Review | D34: 15 | E34: ILT | F34: Facilitator Guide | I34: ⚠️ DRAFT — I can summarize UA, MIMO/Stats, and documentation standards. | J34: ⚠️ DRAFT — What needs another pass tomorrow? | K34: Zoom | M34: Draft
A35: 6 | B35: D6.01 | C35: Day 6 Morning Review | D35: 15 | E35: ILT | F35: Facilitator Guide | I35: ⚠️ DRAFT — I can recall Day 5 concepts. | J35: ⚠️ DRAFT — Open questions? | K35: Zoom | L35: 1.5 practice / 1 hr admin time in afternoon | M35: Draft
A36: 6 | B36: D6.02 | C36: Meter Concepts: How Submetering Works & Why It Matters | D36: 30 | E36: ILT | F36: Facilitator Guide | G36: Slide Deck | I36: ⚠️ DRAFT — I understand what submetering is, how it differs from RUBS, and why properties choose it. | J36: ⚠️ DRAFT — Is this a submetered property? What does that mean for billing? | K36: Skywalker, YODA | M36: Draft
A37: 6 | B37: D6.03 | C37: Submetered Billing Methods & Math | D37: 60 | E37: ILT | F37: Facilitator Guide | G37: Job Aid | H37: Math Worksheet | I37: ⚠️ DRAFT — I can perform the math behind submetered billing — rates, usage, expense allocation. | J37: ⚠️ DRAFT — Did the math come out right? Does this rate match the contract? | K37: YODA, Skywalker, Calculator | M37: Draft
A38: 6 | B38: D6.04 | C38: Connecting Meters to the Workflow | D38: 30 | E38: ILT | F38: Facilitator Guide | G38: Job Aid | I38: ⚠️ DRAFT — I can place meter steps within the broader prep/calc workflow. | J38: ⚠️ DRAFT — Where do meters fit in this property's cycle? | K38: YODA, Skywalker | M38: Draft
A39: 6 | B39: D6.05 | C39: What Do You Need to Do — Step-by-Step Meter Review | D39: 45 | E39: Job Aid | F39: Facilitator Guide | G39: Step-by-Step Doc | I39: ⚠️ DRAFT — I can walk through a meter review checklist start to finish. | J39: ⚠️ DRAFT — Did I check every step? Anything missing? | K39: YODA, Skywalker, ABP | M39: Draft
A40: 6 | B40: D6.06 | C40: Verifying System Estimations & Initial Meter Reads | D40: 30 | E40: ILT | F40: Facilitator Guide | G40: Job Aid | I40: ⚠️ DRAFT — I can verify system-generated estimations and check initial meter reads before importing. | J40: ⚠️ DRAFT — Does the estimation make sense? Are the reads in range? | K40: YODA, ABP, Construct | M40: Draft
...

Sheet Day Summary
A1: Billing EL Program — Day Summary
A2: Daily content budget: 540 min | Lunch + 2 breaks (90 min) auto-subtracted from the 10.5-hr day
A4: Day | B4: Scheduled Minutes | C4: Daily Budget | D4: Remaining | E4: Fill % | F4: Modules | G4: Draft Modules | H4: Status
A5: 3 | B5: =SUMIF('Content Inventory'!A:A,A5,'Content Inventory'!D:D) -> 400 | C5: 540 | D5: =C5-B5 -> 140 | E5: =IFERROR(B5/C5,0) -> 0.74074074 | F5: =COUNTIF('Content Inventory'!A:A,A5) -> 11 | G5: =COUNTIFS('Content Inventory'!A:A,A5,'Content Inventory'!M:M,"Draft") -> 8 | H5: =IF(B5>C5,"OVER",IF(B5=C5,"FULL",IF(B5>=C5*0.9,"NEAR FULL","UNDER"))) -> UNDER
A6: 4 | B6: =SUMIF('Content Inventory'!A:A,A6,'Content Inventory'!D:D) -> 365 | C6: 540 | D6: =C6-B6 -> 175 | E6: =IFERROR(B6/C6,0) -> 0.67592593 | F6: =COUNTIF('Content Inventory'!A:A,A6) -> 11 | G6: =COUNTIFS('Content Inventory'!A:A,A6,'Content Inventory'!M:M,"Draft") -> 10 | H6: =IF(B6>C6,"OVER",IF(B6=C6,"FULL",IF(B6>=C6*0.9,"NEAR FULL","UNDER"))) -> UNDER
A7: 5 | B7: =SUMIF('Content Inventory'!A:A,A7,'Content Inventory'!D:D) -> 380 | C7: 540 | D7: =C7-B7 -> 160 | E7: =IFERROR(B7/C7,0) -> 0.7037037 | F7: =COUNTIF('Content Inventory'!A:A,A7) -> 11 | G7: =COUNTIFS('Content Inventory'!A:A,A7,'Content Inventory'!M:M,"Draft") -> 11 | H7: =IF(B7>C7,"OVER",IF(B7=C7,"FULL",IF(B7>=C7*0.9,"NEAR FULL","UNDER"))) -> UNDER
A8: 6 | B8: =SUMIF('Content Inventory'!A:A,A8,'Content Inventory'!D:D) -> 435 | C8: 540 | D8: =C8-B8 -> 105 | E8: =IFERROR(B8/C8,0) -> 0.80555556 | F8: =COUNTIF('Content Inventory'!A:A,A8) -> 13 | G8: =COUNTIFS('Content Inventory'!A:A,A8,'Content Inventory'!M:M,"Draft") -> 13 | H8: =IF(B8>C8,"OVER",IF(B8=C8,"FULL",IF(B8>=C8*0.9,"NEAR FULL","UNDER"))) -> UNDER
A9: 7 | B9: =SUMIF('Content Inventory'!A:A,A9,'Content Inventory'!D:D) -> 375 | C9: 540 | D9: =C9-B9 -> 165 | E9: =IFERROR(B9/C9,0) -> 0.69444444 | F9: =COUNTIF('Content Inventory'!A:A,A9) -> 10 | G9: =COUNTIFS('Content Inventory'!A:A,A9,'Content Inventory'!M:M,"Draft") -> 10 | H9: =IF(B9>C9,"OVER",IF(B9=C9,"FULL",IF(B9>=C9*0.9,"NEAR FULL","UNDER"))) -> UNDER
A10: 8 | B10: =SUMIF('Content Inventory'!A:A,A10,'Content Inventory'!D:D) -> 405 | C10: 540 | D10: =C10-B10 -> 135 | E10: =IFERROR(B10/C10,0) -> 0.75 | F10: =COUNTIF('Content Inventory'!A:A,A10) -> 12 | G10: =COUNTIFS('Content Inventory'!A:A,A10,'Content Inventory'!M:M,"Draft") -> 12 | H10: =IF(B10>C10,"OVER",IF(B10=C10,"FULL",IF(B10>=C10*0.9,"NEAR FULL","UNDER"))) -> UNDER
A11: 9 | B11: =SUMIF('Content Inventory'!A:A,A11,'Content Inventory'!D:D) -> 420 | C11: 540 | D11: =C11-B11 -> 120 | E11: =IFERROR(B11/C11,0) -> 0.77777778 | F11: =COUNTIF('Content Inventory'!A:A,A11) -> 11 | G11: =COUNTIFS('Content Inventory'!A:A,A11,'Content Inventory'!M:M,"Draft") -> 11 | H11: =IF(B11>C11,"OVER",IF(B11=C11,"FULL",IF(B11>=C11*0.9,"NEAR FULL","UNDER"))) -> UNDER
A12: 10 | B12: =SUMIF('Content Inventory'!A:A,A12,'Content Inventory'!D:D) -> 390 | C12: 540 | D12: =C12-B12 -> 150 | E12: =IFERROR(B12/C12,0) -> 0.72222222 | F12: =COUNTIF('Content Inventory'!A:A,A12) -> 9 | G12: =COUNTIFS('Content Inventory'!A:A,A12,'Content Inventory'!M:M,"Draft") -> 8 | H12: =IF(B12>C12,"OVER",IF(B12=C12,"FULL",IF(B12>=C12*0.9,"NEAR FULL","UNDER"))) -> UNDER
A13: TOTAL | B13: =SUM(B5:B12) -> 3170 | C13: =SUM(C5:C12) -> 4320 | D13: =C13-B13 -> 1150 | E13: =IFERROR(B13/C13,0) -> 0.7337963 | F13: =SUM(F5:F12) -> 88 | G13: =SUM(G5:G12) -> 83

Sheet Week View
A1: Week View
A3: Week | B3: Days | C3: Total Scheduled Min | D3: Total Budget | E3: Fill % | F3: Total Modules
A4: Week 1 (Days 3-5) | B4: 3, 4, 5 | C4: ='Day Summary'!B5+'Day Summary'!B6+'Day Summary'!B7 -> 1145 | D4: ='Day Summary'!C5+'Day Summary'!C6+'Day Summary'!C7 -> 1620 | E4: =IFERROR(C4/D4,0) -> 0.70679012 | F4: ='Day Summary'!F5+'Day Summary'!F6+'Day Summary'!F7 -> 33
A5: Week 2 (Days 6-10) | B5: 6, 7, 8, 9, 10 | C5: ='Day Summary'!B8+'Day Summary'!B9+'Day Summary'!B10+'Day Summary'!B11+'Day Summary'!B12 -> 2025 | D5: ='Day Summary'!C8+'Day Summary'!C9+'Day Summary'!C10+'Day Summary'!C11+'Day Summary'!C12 -> 2700 | E5: =IFERROR(C5/D5,0) -> 0.75 | F5: ='Day Summary'!F8+'Day Summary'!F9+'Day Summary'!F10+'Day Summary'!F11+'Day Summary'!F12 -> 55

Sheet Legend
A1: Dashboard Legend & Settings
A3: Status Codes
A4: Built | B4: Content is finalized or in active stakeholder review.
A5: Draft | B5: ⚠️ Auto-filled best-guess. Needs SME review before finalization.
A8: Content Type Colors
A9: ILT
A10: eLearning
A11: Blended
A12: Simulation
A13: Scenario
A14: Activity
A15: Assessment
A16: Job Aid
A17: OTJ
A20: Time Math
A21: Daily content budget | B21: 540 min (9 hours)
A22: Lunch (auto-subtracted from total day) | B22: 60 min
A23: Breaks (2 × 15 min, auto-subtracted) | B23: 30 min
A24: Total non-content time per day | B24: 90 min
A25: Implied total class day | B25: 630 min (10.5 hrs) — adjust to your schedule
A27: OTJ Handling
A28: Tag OTJ rows with Content Type = 'OTJ' in Content Inventory.
A29: OTJ counts toward the day's total minutes AND appears as its own block in day views.
